Workbook

Sheet Read Me
B2: Summer 2027 Internship Application Tracker
B3: Abdullah Zubair · MSCS, Columbia University (Fall 2026) · built 2026-08-06
B5: What this is | C5: 1,659 live internship postings across 685 distinct US employers, harvested from 60+ sources. Every row carries a real apply link that was read off a live page — no link was constructed or guessed.
B7: Tabs | C7: Tracker — the postings, sorted best-fit first. Sources — where the data came from. Summary — live counts that update as you work.
B9: How to work it | C9: Filter the Tracker tab and work top-down. Priority column A is the ranking:
B10: A — apply first | C10: Vision/AI or research roles at AI-first or top-tier employers, Summer 2027, sponsor-friendly.
B11: B — strong fit | C11: Strong on most axes — apply in week one.
B12: C — worth applying | C12: Solid general SWE/ML at good employers, or off-term timing.
B13: D — volume / backup | C13: Real openings, weaker fit to your CV+product profile. Batch these.
B15: Columns you fill in | C15: M through Q are yours — shaded yellow. Status (M) is a dropdown.
B17: Example row | C17: This is the format expected in your columns — it is an illustration, not a real application:
C18: Status | Date Applied | Referral? | Follow-up Due | My Notes
C19: Applied | 2026-09-14 | Yes — Sara (Columbia alum) | 2026-09-28 | Referred via alum; OA expected ~2wks
B21: Visa column (H) | C21: You are on an F-1, so this matters. Roles requiring US citizenship, permanent residency or an active security clearance were REMOVED — 292 rows were dropped on that basis, so nothing in this workbook is a clearance dead end.
C23: "Known high-volume H-1B sponsor" = employer has a documented track record of sponsoring, so CPT/OPT is routine. "Not stated" = the posting was silent; confirm before investing time in a long application.
B25: Honest caveats | C25: Read these before you trust a row:
C26: • Term is "Unknown" on 608 rows — the source table did not state a season. Most are Summer 2027, but confirm on the posting.
C27: • Aggregators refresh daily to every 15 minutes; a small number of rows will have closed between harvest and your click.
C28: • Rows sourced via ApplyGuy are one redirect hop from the true ATS posting (flagged in Notes).
C29: • Visa emoji on the community GitHub lists are contributor-supplied and occasionally inconsistent — treat column H as a strong hint, not a guarantee.
C30: • A research fleet was cut short by a credit limit mid-run, so per-company career-page sweeps (FAANG, AI labs, quant, etc.) are only partially covered. The aggregator harvest is deep; the direct-employer sweep is not. See Sources tab.

Sheet Tracker
A1: Priority | B1: Fit | C1: Company | D1: Role | E1: Category | F1: Location | G1: Term | H1: Visa Signal | I1: Apply Link | J1: Posted | K1: Source | L1: Source Notes | M1: Status | N1: Date Applied | O1: Referral? | P1: Follow-up Due | Q1: My Notes
A2: A — apply first | B2: 101 | C2: NVIDIA | D2: PhD Research Intern, Generative AI - 2026 | E2: ML/AI | F2: Santa Clara, CA | G2: Fall 2026 | H2: Known high-volume H-1B sponsor — CPT/OPT routinely accepted | I2: Apply → nvidia.wd5.myworkdayjobs.com/nvidiaexternalcareersite/job/ | K2: zapplyjobs/Internships-2027 | L2: PhD-targeted; H-1B sponsor
A3: A — apply first | B3: 95 | C3: TikTok/ByteDance | D3: AI Perception Intern - Pico | E3: CV/Robotics | F3: San Jose, CA | G3: Summer 2027 | H3: Known high-volume H-1B sponsor — CPT/OPT routinely accepted | I3: Apply → jobs.bytedance.com/en/position/7665457718334425349/detail | J3: 2026-08-03 | K3: SuryaHarikrishnan/internship-tracker | L3: XR perception on Pico headsets; top CV match
A4: A — apply first | B4: 95 | C4: TikTok/ByteDance | D4: Applied Scientist Intern, Trust and Safety, Multimodal Foundation Model | E4: CV/Robotics | F4: Seattle, WA | G4: Summer 2027 | H4: Known high-volume H-1B sponsor — CPT/OPT routinely accepted | I4: Apply → lifeattiktok.com/search/7633668456744503557 | K4: speedyapply/2027-AI-College-Jobs | L4: PhD-level; multimodal - CV-relevant
A5: A — apply first | B5: 95 | C5: TikTok/ByteDance | D5: Applied Scientist Intern, Trust and Safety, Multimodal Foundation Model | E5: CV/Robotics | F5: San Jose, CA | G5: Summer 2027 | H5: Known high-volume H-1B sponsor — CPT/OPT routinely accepted | I5: Apply → lifeattiktok.com/search/7633670871815670069 | K5: speedyapply/2027-AI-College-Jobs | L5: PhD-level; multimodal - CV-relevant
A6: A — apply first | B6: 95 | C6: TikTok/ByteDance | D6: Student Researcher - Multimodal Interaction & World Model - Seed | E6: CV/Robotics | F6: San Jose, CA | G6: Summer 2027 | H6: Known high-volume H-1B sponsor — CPT/OPT routinely accepted | I6: Apply → joinbytedance.com/search/7623548747208739077 | K6: sndsh404/summer-2027-internships README | L6: CV-relevant
A7: A — apply first | B7: 95 | C7: TikTok/ByteDance | D7: Video/Image AI/ML Software Engineer Intern - Multimedia | E7: CV/Robotics | F7: San Diego, CA | G7: Summer 2027 | H7: Known high-volume H-1B sponsor — CPT/OPT routinely accepted | I7: Apply → jobs.bytedance.com/en/position/7670354329765464373/detail | J7: 2026-08-06 | K7: SimplifyJobs Summer2027-Internships README | L7: CV-relevant
A8: A — apply first | B8: 94 | C8: NVIDIA | D8: Software Engineering Intern (Autonomous Vehicles) | E8: CV/Robotics | F8: Santa Clara, CA | G8: Fall 2026 | H8: Known high-volume H-1B sponsor — CPT/OPT routinely accepted | I8: Apply → jobright.ai/jobs/info/6a240e51757ade085b6afa5a | J8: 2026-06-17 | K8: jobright-ai/2026-Software-Engineer-Internship | L8: Strong CV match; repo last updated 2026-06-17 - verify still open
A9: A — apply first | B9: 94 | C9: NVIDIA | D9: Software Engineering Intern, Robot Learning Platform | E9: CV/Robotics | F9: Santa Clara, CA | G9: Fall 2026 | H9: Known high-volume H-1B sponsor — CPT/OPT routinely accepted | I9: Apply → nvidia.wd5.myworkdayjobs.com/NVIDIAExternalCareerSite/job/ | J9: 2026-04-22 | K9: vanshb03/Summer2027-Internships OFFSEASON_README (dev) | L9: Robot learning platform - CV/robotics relevant
A10: A — apply first | B10: 94 | C10: NVIDIA | D10: Software Engineering Intern, Robot Learning Platform - Fall 2026 | E10: CV/Robotics | F10: Not specified | G10: Fall 2026 | H10: Known high-volume H-1B sponsor — CPT/OPT routinely accepted | I10: Apply → nvidia.wd5.myworkdayjobs.com/en-US/NVIDIAExternalCareerSit | K10: NVIDIA Workday careers | L10: Robot learning; strong CV/RL fit
A11: A — apply first | B11: 94 | C11: NVIDIA | D11: Systems Software Engineer Intern, Metropolis | E11: CV/Robotics | F11: Santa Clara, CA | G11: Fall 2026 | H11: Known high-volume H-1B sponsor — CPT/OPT routinely accepted | I11: Apply → nvidia.wd5.myworkdayjobs.com/NVIDIAExternalCareerSite/job/ | J11: 2026-05-14 | K11: vanshb03/Summer2027-Internships OFFSEASON_README (dev) | L11: NVIDIA vision AI platform, CV-relevant; page said apps open til May 17 2026 - verify
A12: A — apply first | B12: 94 | C12: NVIDIA | D12: Systems Software Engineer Intern, Metropolis - Fall 2026 | E12: CV/Robotics | F12: Not specified | G12: Fall 2026 | H12: Known high-volume H-1B sponsor — CPT/OPT routinely accepted | I12: Apply → nvidia.wd5.myworkdayjobs.com/en-US/NVIDIAExternalCareerSit | K12: NVIDIA Workday careers | L12: Metropolis = NVIDIA vision AI platform; top CV fit
A13: A — apply first | B13: 88 | C13: Netflix | D13: Video Algorithms Intern - Video Coding - Gaussian Splatting - Fall 2026 | E13: CV/Robotics | F13: Los Gatos, CA | G13: Fall 2026 | H13: Known high-volume H-1B sponsor — CPT/OPT routinely accepted | I13: Apply → netflix.wd108.myworkdayjobs.com/en-US/netflix/job/Los-Gato | J13: 2026-04-28 | K13: speedyapply/2027-AI-College-Jobs | L13: CV-relevant: Gaussian splatting
A14: A — apply first | B14: 88 | C14: TikTok/ByteDance | D14: Research Scientist Intern, TikTok Search / Generative AI LLM | E14: ML/AI | F14: San Jose, CA | G14: Summer 2027 | H14: Known high-volume H-1B sponsor — CPT/OPT routinely accepted | I14: Apply → lifeattiktok.com/search/7629250876813642037 | K14: speedyapply/2027-AI-College-Jobs | L14: PhD-level; 2027 start
A15: A — apply first | B15: 87 | C15: NVIDIA | D15: Agentic AI Solution Engineering Intern - Fall 2026 | E15: ML/AI | F15: Austin, TX | G15: Fall 2026 | H15: Known high-volume H-1B sponsor — CPT/OPT routinely accepted | I15: Apply → nvidia.wd5.myworkdayjobs.com/NVIDIAExternalCareerSite/job/ | K15: skarazan/southeast-tech-internships-2026-2027 (GitHub aggregator)
A16: A — apply first | B16: 87 | C16: NVIDIA | D16: Applied Deep Learning PhD Research Intern, Reinforcement Learning for LLMs | E16: ML/AI | F16: Santa Clara, CA | G16: Fall 2026 | H16: Known high-volume H-1B sponsor — CPT/OPT routinely accepted | I16: Apply → nvidia.wd5.myworkdayjobs.com/en-US/nvidiaexternalcareersit | K16: speedyapply/2027-AI-College-Jobs | L16: PhD-level; RL for LLMs
A17: A — apply first | B17: 87 | C17: NVIDIA | D17: Applied Research Intern, NLP - Fall 2026 | E17: ML/AI | F17: Santa Clara, CA | G17: Fall 2026 | H17: Known high-volume H-1B sponsor — CPT/OPT routinely accepted | I17: Apply → nvidia.wd5.myworkdayjobs.com/NVIDIAExternalCareerSite/job/ | J17: 2026-07-01 | K17: zshah101/Automated-List-Of-Summer-2027-and-Fall-2026-Tech-Internships | L17: NLP applied research
A18: A — apply first | B18: 87 | C18: NVIDIA | D18: Software Engineering Intern - JAX - Fall 2026 | E18: ML/AI | F18: Santa Clara, CA | G18: Fall 2026 | H18: Known high-volume H-1B sponsor — CPT/OPT routinely accepted | I18: Apply → nvidia.wd5.myworkdayjobs.com/en-US/nvidiaexternalcareersit | J18: 2026-06-15 | K18: speedyapply/2027-SWE-College-Jobs (USA intern table) | L18: $62/hr; JAX/ML compiler
A19: A — apply first | B19: 87 | C19: NVIDIA | D19: Software Engineering Intern, AI Tools - Fall 2026 | E19: ML/AI | F19: Not specified | G19: Fall 2026 | H19: Known high-volume H-1B sponsor — CPT/OPT routinely accepted | I19: Apply → nvidia.wd5.myworkdayjobs.com/en-US/NVIDIAExternalCareerSit | K19: NVIDIA Workday careers
A20: A — apply first | B20: 87 | C20: NVIDIA | D20: Software Engineering Intern, Dynamo - Fall 2026 | E20: ML/AI | F20: Not specified | G20: Fall 2026 | H20: Known high-volume H-1B sponsor — CPT/OPT routinely accepted | I20: Apply → nvidia.wd5.myworkdayjobs.com/en-US/NVIDIAExternalCareerSit | K20: NVIDIA Workday careers | L20: Dynamo LLM inference stack
A21: A — apply first | B21: 87 | C21: NVIDIA | D21: Software Engineering Intern, Dynamo - Fall 2026 | E21: ML/AI | F21: Santa Clara, CA | G21: Fall 2026 | H21: Known high-volume H-1B sponsor — CPT/OPT routinely accepted | I21: Apply → applyguy.ai/jobs?company=NVIDIA&job=6b556750-92e8-4d68-877 | J21: 2026-08-06 | K21: ApplyGuy/2027-Internships | L21: Dynamo LLM serving team
A22: A — apply first | B22: 86 | C22: NVIDIA | D22: Quantum Error Correction Research Scientist Intern | E22: Research | F22: Remote (US) | G22: Fall 2026 | H22: Known high-volume H-1B sponsor — CPT/OPT routinely accepted | I22: Apply → nvidia.wd5.myworkdayjobs.com/en-US/nvidiaexternalcareersit | K22: speedyapply/2027-AI-College-Jobs | L22: $62/hr
A23: A — apply first | B23: 86 | C23: NVIDIA | D23: Quantum Research Scientist Intern - Fall 2026 | E23: Research | F23: Remote (US) | G23: Fall 2026 | H23: Known high-volume H-1B sponsor — CPT/OPT routinely accepted | I23: Apply → nvidia.wd5.myworkdayjobs.com/NVIDIAExternalCareerSite/job/ | J23: 2026-05-27 | K23: zshah101/Automated-List-Of-Summer-2027-and-Fall-2026-Tech-Internships
A24: A — apply first | B24: 86 | C24: NVIDIA | D24: Synthetic Data Generation and User Simulation PhD Research Intern - Fall 2026 | E24: Research | F24: Remote (US) | G24: Fall 2026 | H24: Known high-volume H-1B sponsor — CPT/OPT routinely accepted | I24: Apply → nvidia.wd5.myworkdayjobs.com/NVIDIAExternalCareerSite/job/ | K24: skarazan/southeast-tech-internships-2026-2027 (GitHub aggregator)
A25: A — apply first | B25: 83 | C25: Meta | D25: Research Scientist Intern - Applied Vision and Image Quality - PhD | E25: CV/Robotics | F25: Redmond, WA | G25: Unknown | H25: Known high-volume H-1B sponsor — CPT/OPT routinely accepted | I25: Apply → metacareers.com/jobs/1422892385992613 | J25: 2026-05-20 | K25: speedyapply/2027-AI-College-Jobs | L25: PhD-level; strong CV match
A26: A — apply first | B26: 83 | C26: Meta | D26: Research Scientist Intern - Machine Perception for Input and Interaction - PhD | E26: CV/Robotics | F26: Redmond, WA | G26: Unknown | H26: Known high-volume H-1B sponsor — CPT/OPT routinely accepted | I26: Apply → metacareers.com/jobs/779670167783218 | J26: 2026-05-06 | K26: speedyapply/2027-AI-College-Jobs | L26: PhD-level; machine perception, CV match
A27: A — apply first | B27: 83 | C27: Meta | D27: Research Scientist Intern, 3D Vision & World Simulation | E27: CV/Robotics | F27: Redmond, WA | G27: Unknown | H27: Known high-volume H-1B sponsor — CPT/OPT routinely accepted | I27: Apply → metacareers.com/jobs/2839011673109571 | K27: speedyapply/2027-AI-College-Jobs | L27: PhD-level; 3D vision - highly CV-relevant
A28: A — apply first | B28: 83 | C28: NVIDIA | D28: PhD Research Intern, Security and Privacy - Fall 2026 | E28: Research | F28: Santa Clara, CA | G28: Fall 2026 | H28: Known high-volume H-1B sponsor — CPT/OPT routinely accepted | I28: Apply → nvidia.wd5.myworkdayjobs.com/nvidiaexternalcareersite/job/ | K28: zapplyjobs/Internships-2027 (Product, Design & Research section) | L28: zapply visa col: H-1B Co.; age 1mo; PhD-level
A29: A — apply first | B29: 83 | C29: NVIDIA | D29: Quantum Research Scientist Intern | E29: Research | F29: Santa Clara, CA | G29: Fall 2026 | H29: Known high-volume H-1B sponsor — CPT/OPT routinely accepted | I29: Apply → nvidia.wd5.myworkdayjobs.com/NVIDIAExternalCareerSite/job/ | J29: 2026-05-19 | K29: vanshb03/Summer2027-Internships OFFSEASON_README
A30: A — apply first | B30: 83 | C30: TikTok/ByteDance | D30: Machine Learning Engineer Intern - Data Search - Visual Search | E30: CV/Robotics | F30: San Jose, CA | G30: Unknown | H30: Known high-volume H-1B sponsor — CPT/OPT routinely accepted | I30: Apply → lifeattiktok.com/search/7667349591727278341 | J30: 2026-08-04 | K30: DereC4/internships-and-newgrad (GitHub aggregator) | L30: Masters/PhD-level role; term not stated in listing
A31: A — apply first | B31: 83 | C31: TikTok/ByteDance | D31: Research Intern - Video Data Compression | E31: CV/Robotics | F31: San Diego, CA | G31: Unknown | H31: Known high-volume H-1B sponsor — CPT/OPT routinely accepted | I31: Apply → jobs.bytedance.com/en/position/7538674634397813010/detail | J31: 2026-08-06 | K31: zapplyjobs/Internships-2027 | L31: Video codecs; CV-relevant
A32: A — apply first | B32: 82 | C32: NVIDIA | D32: Software Engineer Intern, Dynamo | E32: ML/AI | F32: Santa Clara, CA | G32: Unknown | H32: Known high-volume H-1B sponsor — CPT/OPT routinely accepted | I32: Apply → simplify.jobs/p/2ccc5c31-d719-47e7-ab38-b42010d3a585/Softw | K32: Simplify Jobs - Bay Area Internships | L32: LLM inference infra; $20-71/hr
A33: A — apply first | B33: 81 | C33: Citadel Securities | D33: Machine Learning Researcher PhD Intern | E33: ML/AI | F33: Chicago, IL; New York, NY | G33: Summer 2027 | H33: Known high-volume H-1B sponsor — CPT/OPT routinely accepted | I33: Apply → citadelsecurities.com/careers/details/machine-learning-res | K33: northwesternfintech/2027QuantInternships | L33: PhD only
A34: A — apply first | B34: 81 | C34: Jane Street | D34: Machine Learning Engineer Intern | E34: ML/AI | F34: New York, NY | G34: Summer 2027 | H34: Known high-volume H-1B sponsor — CPT/OPT routinely accepted | I34: Apply → janestreet.com/join-jane-street/position/8611307002/ | J34: 2026-07-24 | K34: vanshb03/Summer2027-Internships README (mirror of community list)
A35: A — apply first | B35: 81 | C35: Jane Street | D35: Machine Learning Researcher Intern | E35: ML/AI | F35: New York, NY | G35: Summer 2027 | H35: Known high-volume H-1B sponsor — CPT/OPT routinely accepted | I35: Apply → janestreet.com/join-jane-street/position/8384490002/ | J35: 2026-07-24 | K35: vanshb03/Summer2027-Internships README (mirror of community list)
A36: A — apply first | B36: 81 | C36: TikTok/ByteDance | D36: Research Scientist Intern - Multi-modal Agentic Databases | E36: CV/Robotics | F36: Seattle, WA | G36: Summer 2027 | H36: Known high-volume H-1B sponsor — CPT/OPT routinely accepted | I36: Apply → jobs.bytedance.com/en/position/7667380184615127301/detail | J36: 2026-08-03 | K36: SuryaHarikrishnan/internship-tracker | L36: Multi-modal; CV-relevant
A37: A — apply first | B37: 81 | C37: TikTok/ByteDance | D37: Research Scientist Intern - Multimedia Streaming | E37: CV/Robotics | F37: San Diego, CA | G37: Summer 2027 | H37: Known high-volume H-1B sponsor — CPT/OPT routinely accepted | I37: Apply → simplify.jobs/p/50940dc5-4b2f-4f49-983e-f589769f3848/Resea | K37: Simplify Jobs - Top Summer Internships 2027 | L37: Video/multimedia - CV-adjacent
A38: A — apply first | B38: 81 | C38: TikTok/ByteDance | D38: Software Engineer Intern - Agentic Creation-Effect Platform | E38: CV/Robotics | F38: San Jose, CA | G38: Summer 2027 | H38: Known high-volume H-1B sponsor — CPT/OPT routinely accepted | I38: Apply → lifeattiktok.com/search/7668445566565321013 | J38: 2026-08-03 | K38: SuryaHarikrishnan/internship-tracker | L38: Agentic + AR effects; CV-adjacent
A39: A — apply first | B39: 81 | C39: TikTok/ByteDance | D39: Software Engineer Intern - Effects Performance | E39: CV/Robotics | F39: San Jose, CA | G39: Summer 2027 | H39: Known high-volume H-1B sponsor — CPT/OPT routinely accepted | I39: Apply → lifeattiktok.com/search/7668725183121000757 | J39: 2026-08-04 | K39: SuryaHarikrishnan/internship-tracker | L39: AR effects performance; CV-relevant
A40: A — apply first | B40: 81 | C40: TikTok/ByteDance | D40: Software Engineer Intern - Intelligent Creation-Camera | E40: CV/Robotics | F40: San Jose, CA | G40: Summer 2027 | H40: Known high-volume H-1B sponsor — CPT/OPT routinely accepted | I40: Apply → lifeattiktok.com/search/7668862422178318597 | J40: 2026-08-04 | K40: SuryaHarikrishnan/internship-tracker | L40: Camera/imaging team; strong CV match
...

Sheet Summary
B2: Live counts
B3: Formulas read the Tracker tab — these update as you fill in Status.
B5: PIPELINE
B6: Total opportunities in tracker | C6: =COUNTA(Tracker!$C$2:$C$1660) -> 1659
B7: Applications submitted | C7: =COUNTIF(Tracker!$M$2:$M$1660,"Applied")+COUNTIF(Tracker!$M$2:$M$1660,"OA / take-home")+COUNTIF(Tracker!$M$2:$M$1660,"Phone screen")+COUNTIF(Tracker!$M$2:$M$1660,"Onsite / final")+COUNTIF(Tracker!$M$2:$M$1660,"Offer") -> 0 | D7: counts anything past Not started
B8: Not started yet | C8: =COUNTA(Tracker!$C$2:$C$1660)-COUNTA(Tracker!$M$2:$M$1660)+COUNTIF(Tracker!$M$2:$M$1660,"Not started") -> 1659
B9: In interview process | C9: =COUNTIF(Tracker!$M$2:$M$1660,"OA / take-home")+COUNTIF(Tracker!$M$2:$M$1660,"Phone screen")+COUNTIF(Tracker!$M$2:$M$1660,"Onsite / final") -> 0
B10: Offers | C10: =COUNTIF(Tracker!$M$2:$M$1660,"Offer") -> 0
B11: Rejected | C11: =COUNTIF(Tracker!$M$2:$M$1660,"Rejected") -> 0
B12: Response rate | C12: =IFERROR((COUNTIF(Tracker!$M$2:$M$1660,"OA / take-home")+COUNTIF(Tracker!$M$2:$M$1660,"Phone screen")+COUNTIF(Tracker!$M$2:$M$1660,"Onsite / final")+COUNTIF(Tracker!$M$2:$M$1660,"Offer"))/(COUNTIF(Tracker!$M$2:$M$1660,"Applied")+COUNTIF(Tracker!$M$2:$M$1660,"OA / take-home")+COUNTIF(Tracker!$M$2:$M$1660,"Phone screen")+COUNTIF(Tracker!$M$2:$M$1660,"Onsite / final")+COUNTIF(Tracker!$M$2:$M$1660,"Offer")),"—") -> —
B14: BY PRIORITY
B15: A — apply first | C15: =COUNTIF(Tracker!$A$2:$A$1660,"A — apply first") -> 43
B16: B — strong fit | C16: =COUNTIF(Tracker!$A$2:$A$1660,"B — strong fit") -> 159
B17: C — worth applying | C17: =COUNTIF(Tracker!$A$2:$A$1660,"C — worth applying") -> 315
B18: D — volume / backup | C18: =COUNTIF(Tracker!$A$2:$A$1660,"D — volume / backup") -> 1142
B20: BY CATEGORY
B21: SWE | C21: =COUNTIF(Tracker!$E$2:$E$1660,"SWE") -> 661
B22: ML/AI | C22: =COUNTIF(Tracker!$E$2:$E$1660,"ML/AI") -> 324
B23: CV/Robotics | C23: =COUNTIF(Tracker!$E$2:$E$1660,"CV/Robotics") -> 143
B24: Data | C24: =COUNTIF(Tracker!$E$2:$E$1660,"Data") -> 142
B25: Research | C25: =COUNTIF(Tracker!$E$2:$E$1660,"Research") -> 111
B26: Quant | C26: =COUNTIF(Tracker!$E$2:$E$1660,"Quant") -> 101
B27: Hardware | C27: =COUNTIF(Tracker!$E$2:$E$1660,"Hardware") -> 68
B28: Product | C28: =COUNTIF(Tracker!$E$2:$E$1660,"Product") -> 55
B29: Other | C29: =COUNTIF(Tracker!$E$2:$E$1660,"Other") -> 33
B30: Security | C30: =COUNTIF(Tracker!$E$2:$E$1660,"Security") -> 21
B32: BY TERM
B33: Unknown | C33: =COUNTIF(Tracker!$G$2:$G$1660,"Unknown") -> 608 | D33: source table did not state a season
B34: Fall 2026 | C34: =COUNTIF(Tracker!$G$2:$G$1660,"Fall 2026") -> 465
B35: Summer 2027 | C35: =COUNTIF(Tracker!$G$2:$G$1660,"Summer 2027") -> 458
B36: Off-cycle | C36: =COUNTIF(Tracker!$G$2:$G$1660,"Off-cycle") -> 92
B37: Spring 2027 | C37: =COUNTIF(Tracker!$G$2:$G$1660,"Spring 2027") -> 36
B39: VISA POSTURE (F-1)
B40: Known high-volume H-1B sponsor | C40: =COUNTIF(Tracker!$H$2:$H$1660,"Known high-volume*") -> 583 | D40: CPT/OPT routine here
B41: No restriction stated in posting | C41: =COUNTIF(Tracker!$H$2:$H$1660,"No restriction*") -> 461
B42: Not stated — verify first | C42: =COUNTIF(Tracker!$H$2:$H$1660,"Not stated*") -> 588
B43: Posting states no sponsorship | C43: =COUNTIF(Tracker!$H$2:$H$1660,"Posting states no*") -> 27 | D43: deprioritised in Fit score
B44: Citizenship / clearance required | C44: 0 | D44: 292 such rows were removed before delivery
B46: TOP EMPLOYERS BY OPENING COUNT
B47: TikTok/ByteDance | C47: =COUNTIF(Tracker!$C$2:$C$1660,"TikTok/ByteDance") -> 159
...

Sheet Sources
A1: Source | B1: Rows contributed | C1: Representative URL
A2: zapplyjobs/Internships-2027 | B2: 160 | C2: https://github.com/zapplyjobs/Internships-2027
A3: speedyapply/2027-AI-College-Jobs | B3: 145 | C3: https://github.com/speedyapply/2027-AI-College-Jobs
A4: SuryaHarikrishnan/internship-tracker | B4: 132 | C4: https://github.com/SuryaHarikrishnan/internship-tracker/blob/master/listings/data-science-ai-machine-learning.md
A5: keryx internship database (GodlyDonuts/keryx) | B5: 119 | C5: https://github.com/GodlyDonuts/keryx/blob/main/internships/fall-2026.md
A6: skarazan/southeast-tech-internships-2026-2027 (GitHub aggregator) | B6: 102 | C6: https://github.com/skarazan/southeast-tech-internships-2026-2027
A7: DereC4/internships-and-newgrad (GitHub aggregator) | B7: 98 | C7: https://github.com/DereC4/internships-and-newgrad
A8: ApplyGuy/2027-Internships | B8: 85 | C8: https://github.com/ApplyGuy/2027-Internships
A9: vanshb03/Summer2027-Internships README (mirror of community list) | B9: 76 | C9: https://github.com/vanshb03/Summer2027-Internships
A10: speedyapply/2027-SWE-College-Jobs (USA intern table) | B10: 74 | C10: https://github.com/speedyapply/2027-SWE-College-Jobs
A11: zapplyjobs/Internships-2027 (Hardware & Engineering section) | B11: 66 | C11: https://github.com/zapplyjobs/Internships-2027
A12: sndsh404/summer-2027-internships | B12: 59 | C12: https://github.com/sndsh404/summer-2027-internships
A13: SimplifyJobs Summer2027-Internships Off-Season README | B13: 53 | C13: https://github.com/SimplifyJobs/Summer2027-Internships/blob/dev/README-Off-Season.md
... A64: Ashby job board (Zip) | B64: 1 | C64: https://jobs.ashbyhq.com/zip
A66: TOTAL (pre-dedupe raw rows harvested: 3,742) | B66: =SUM(B2:B64) -> 1659
